[2023-12-21 00:47:19,083] torch.distributed.run: [WARNING] master_addr is only used for static rdzv_backend and when rdzv_endpoint is not specified.
[2023-12-21 00:47:19,083] torch.distributed.run: [WARNING] 
[2023-12-21 00:47:19,083] torch.distributed.run: [WARNING] *****************************************
[2023-12-21 00:47:19,083] torch.distributed.run: [WARNING] Setting OMP_NUM_THREADS environment variable for each process to be 1 in default, to avoid your system being overloaded, please further tune the variable for optimal performance in your application as needed. 
[2023-12-21 00:47:19,083] torch.distributed.run: [WARNING] *****************************************
/home/ztushar1/.conda/envs/df/lib/python3.10/site-packages/accelerate/accelerator.py:384: UserWarning: `log_with=tensorboard` was passed but no supported trackers are currently installed.
  warnings.warn(f"`log_with={log_with}` was passed but no supported trackers are currently installed.")
Detected kernel version 3.10.0, which is below the recommended minimum of 5.5.0; this can cause the process to hang. It is recommended to upgrade the kernel to the minimum version or higher.
/home/ztushar1/.conda/envs/df/lib/python3.10/site-packages/accelerate/accelerator.py:384: UserWarning: `log_with=tensorboard` was passed but no supported trackers are currently installed.
  warnings.warn(f"`log_with={log_with}` was passed but no supported trackers are currently installed.")
/home/ztushar1/.conda/envs/df/lib/python3.10/site-packages/accelerate/accelerator.py:384: UserWarning: `log_with=tensorboard` was passed but no supported trackers are currently installed.
  warnings.warn(f"`log_with={log_with}` was passed but no supported trackers are currently installed.")
/home/ztushar1/.conda/envs/df/lib/python3.10/site-packages/accelerate/accelerator.py:384: UserWarning: `log_with=tensorboard` was passed but no supported trackers are currently installed.
  warnings.warn(f"`log_with={log_with}` was passed but no supported trackers are currently installed.")
  0%|          | 0/2285 [00:00<?, ?it/s]Epoch 0:   0%|          | 0/2285 [00:00<?, ?it/s]Traceback (most recent call last):
  File "/nfs/rs/psanjay/users/ztushar1/diffusers/v2_train.py", line 88, in <module>
    train_loop(config, model, noise_scheduler, optimizer, train_dataloader, lr_scheduler)
  File "/nfs/rs/psanjay/users/ztushar1/diffusers/v2_train_utils.py", line 54, in train_loop
    time_embedding = get_time_embedding(timesteps).to(clean_images.device)
  File "/nfs/rs/psanjay/users/ztushar1/diffusers/v2_train_utils.py", line 108, in get_time_embedding
    x = torch.tensor([timestep], dtype=torch.float32)[:, None] * freqs[None]
ValueError: only one element tensors can be converted to Python scalars
Traceback (most recent call last):
  File "/nfs/rs/psanjay/users/ztushar1/diffusers/v2_train.py", line 88, in <module>
    train_loop(config, model, noise_scheduler, optimizer, train_dataloader, lr_scheduler)
  File "/nfs/rs/psanjay/users/ztushar1/diffusers/v2_train_utils.py", line 54, in train_loop
    time_embedding = get_time_embedding(timesteps).to(clean_images.device)
  File "/nfs/rs/psanjay/users/ztushar1/diffusers/v2_train_utils.py", line 108, in get_time_embedding
    x = torch.tensor([timestep], dtype=torch.float32)[:, None] * freqs[None]
ValueError: only one element tensors can be converted to Python scalars
Traceback (most recent call last):
  File "/nfs/rs/psanjay/users/ztushar1/diffusers/v2_train.py", line 88, in <module>
    train_loop(config, model, noise_scheduler, optimizer, train_dataloader, lr_scheduler)
  File "/nfs/rs/psanjay/users/ztushar1/diffusers/v2_train_utils.py", line 54, in train_loop
    time_embedding = get_time_embedding(timesteps).to(clean_images.device)
  File "/nfs/rs/psanjay/users/ztushar1/diffusers/v2_train_utils.py", line 108, in get_time_embedding
    x = torch.tensor([timestep], dtype=torch.float32)[:, None] * freqs[None]
ValueError: only one element tensors can be converted to Python scalars
Traceback (most recent call last):
  File "/nfs/rs/psanjay/users/ztushar1/diffusers/v2_train.py", line 88, in <module>
    train_loop(config, model, noise_scheduler, optimizer, train_dataloader, lr_scheduler)
  File "/nfs/rs/psanjay/users/ztushar1/diffusers/v2_train_utils.py", line 54, in train_loop
    time_embedding = get_time_embedding(timesteps).to(clean_images.device)
  File "/nfs/rs/psanjay/users/ztushar1/diffusers/v2_train_utils.py", line 108, in get_time_embedding
    x = torch.tensor([timestep], dtype=torch.float32)[:, None] * freqs[None]
ValueError: only one element tensors can be converted to Python scalars
Epoch 0:   0%|          | 0/2285 [00:00<?, ?it/s]
[2023-12-21 00:47:49,498] torch.distributed.elastic.multiprocessing.api: [ERROR] failed (exitcode: 1) local_rank: 0 (pid: 11610) of binary: /home/ztushar1/.conda/envs/df/bin/python
Traceback (most recent call last):
  File "/home/ztushar1/.conda/envs/df/bin/torchrun", line 8, in <module>
    sys.exit(main())
  File "/home/ztushar1/.conda/envs/df/lib/python3.10/site-packages/torch/distributed/elastic/multiprocessing/errors/__init__.py", line 346, in wrapper
    return f(*args, **kwargs)
  File "/home/ztushar1/.conda/envs/df/lib/python3.10/site-packages/torch/distributed/run.py", line 806, in main
    run(args)
  File "/home/ztushar1/.conda/envs/df/lib/python3.10/site-packages/torch/distributed/run.py", line 797, in run
    elastic_launch(
  File "/home/ztushar1/.conda/envs/df/lib/python3.10/site-packages/torch/distributed/launcher/api.py", line 134, in __call__
    return launch_agent(self._config, self._entrypoint, list(args))
  File "/home/ztushar1/.conda/envs/df/lib/python3.10/site-packages/torch/distributed/launcher/api.py", line 264, in launch_agent
    raise ChildFailedError(
torch.distributed.elastic.multiprocessing.errors.ChildFailedError: 
============================================================
v2_train.py FAILED
------------------------------------------------------------
Failures:
[1]:
  time      : 2023-12-21_00:47:49
  host      : g13.cm.cluster
  rank      : 1 (local_rank: 1)
  exitcode  : 1 (pid: 11611)
  error_file: <N/A>
  traceback : To enable traceback see: https://pytorch.org/docs/stable/elastic/errors.html
[2]:
  time      : 2023-12-21_00:47:49
  host      : g13.cm.cluster
  rank      : 2 (local_rank: 2)
  exitcode  : 1 (pid: 11613)
  error_file: <N/A>
  traceback : To enable traceback see: https://pytorch.org/docs/stable/elastic/errors.html
[3]:
  time      : 2023-12-21_00:47:49
  host      : g13.cm.cluster
  rank      : 3 (local_rank: 3)
  exitcode  : 1 (pid: 11616)
  error_file: <N/A>
  traceback : To enable traceback see: https://pytorch.org/docs/stable/elastic/errors.html
------------------------------------------------------------
Root Cause (first observed failure):
[0]:
  time      : 2023-12-21_00:47:49
  host      : g13.cm.cluster
  rank      : 0 (local_rank: 0)
  exitcode  : 1 (pid: 11610)
  error_file: <N/A>
  traceback : To enable traceback see: https://pytorch.org/docs/stable/elastic/errors.html
============================================================
